/*
*** MADE BY MITHION'S .SCHEMATIC TO JAVA CONVERTING TOOL v1.6 ***
*/

package Mod.enchantedwoodlands.Dimension.Structure;
import java.util.Random;

import Mod.enchantedwoodlands.Blocks.Blocks;
import net.minecraft.block.Block;
import net.minecraft.world.World;
import net.minecraft.world.gen.feature.WorldGenerator;

public class DimensionAlter extends WorldGenerator
{
	protected int[] GetValidSpawnBlocks() {
		return new int[] {
			Block.grass.blockID
		};
	}

	public boolean LocationIsValidSpawn(World world, int i, int j, int k){
		int distanceToAir = 0;
		int checkID = world.getBlockId(i, j, k);

		while (checkID != 0){
			distanceToAir++;
			checkID = world.getBlockId(i, j + distanceToAir, k);
		}

		if (distanceToAir > 9){
			return false;
		}
		j += distanceToAir - 1;

		int blockID = world.getBlockId(i, j, k);
		int blockIDAbove = world.getBlockId(i, j+1, k);
		int blockIDBelow = world.getBlockId(i, j-1, k);
		for (int x : GetValidSpawnBlocks()){
			if (blockIDAbove != 0){
				return false;
			}
			if (blockID == x){
				return true;
			}else if (blockID == Block.snow.blockID && blockIDBelow == x){
				return true;
			}
		}
		return false;
	}

	public DimensionAlter() { }

	public boolean generate(World world, Random rand, int i, int j, int k) {
		//check that each corner is one of the valid spawn blocks
		if(!LocationIsValidSpawn(world, i, j, k) || !LocationIsValidSpawn(world, i + 8, j, k) || !LocationIsValidSpawn(world, i + 8, j, k + 13) || !LocationIsValidSpawn(world, i, j, k + 13))
		{
			return false;
		}

		world.setBlock(i + 0, j + 0, k + 0, Block.grass.blockID);
		world.setBlock(i + 0, j + 0, k + 1, Block.grass.blockID);
		world.setBlock(i + 0, j + 0, k + 2, Block.grass.blockID);
		world.setBlock(i + 0, j + 0, k + 3, Block.grass.blockID);
		world.setBlock(i + 0, j + 0, k + 4, Block.grass.blockID);
		world.setBlock(i + 0, j + 0, k + 5, Block.grass.blockID);
		world.setBlock(i + 0, j + 0, k + 6, Block.grass.blockID);
		world.setBlock(i + 0, j + 0, k + 7, Block.grass.blockID);
		world.setBlock(i + 0, j + 0, k + 8, Block.grass.blockID);
		world.setBlock(i + 0, j + 0, k + 9, Block.grass.blockID);
		world.setBlock(i + 0, j + 0, k + 10, Block.grass.blockID);
		world.setBlock(i + 0, j + 0, k + 11, Block.grass.blockID);
		world.setBlock(i + 0, j + 0, k + 12, Block.grass.blockID);
		world.setBlock(i + 0, j + 0, k + 13, Block.grass.blockID);
		world.setBlock(i + 0, j + 1, k + 0, 0);
		world.setBlock(i + 0, j + 1, k + 1, 0);
		world.setBlock(i + 0, j + 1, k + 2, 0);
		world.setBlock(i + 0, j + 1, k + 8, 0);
		world.setBlock(i + 0, j + 1, k + 13, 0);
		world.setBlock(i + 0, j + 2, k + 0, 0);
		world.setBlock(i + 0, j + 2, k + 1, 0);
		world.setBlock(i + 0, j + 2, k + 2, 0);
		world.setBlock(i + 0, j + 2, k + 8, 0);
		world.setBlock(i + 0, j + 2, k + 13, 0);
		world.setBlock(i + 0, j + 3, k + 0, 0);
		world.setBlock(i + 0, j + 3, k + 1, 0);
		world.setBlock(i + 0, j + 3, k + 2, 0);
		world.setBlock(i + 0, j + 3, k + 8, 0);
		world.setBlock(i + 0, j + 3, k + 13, 0);
		world.setBlock(i + 0, j + 4, k + 0, 0);
		world.setBlock(i + 0, j + 4, k + 1, 0);
		world.setBlock(i + 0, j + 4, k + 2, 0);
		world.setBlock(i + 0, j + 4, k + 6, 0);
		world.setBlock(i + 0, j + 4, k + 7, 0);
		world.setBlock(i + 0, j + 4, k + 8, 0);
		world.setBlock(i + 0, j + 4, k + 9, 0);
		world.setBlock(i + 0, j + 4, k + 13, 0);
		world.setBlock(i + 0, j + 5, k + 0, 0);
		world.setBlock(i + 0, j + 5, k + 1, 0);
		world.setBlock(i + 0, j + 5, k + 2, 0);
		world.setBlock(i + 0, j + 5, k + 5, 0);
		world.setBlock(i + 0, j + 5, k + 6, 0);
		world.setBlock(i + 0, j + 5, k + 7, 0);
		world.setBlock(i + 0, j + 5, k + 8, 0);
		world.setBlock(i + 0, j + 5, k + 9, 0);
		world.setBlock(i + 0, j + 5, k + 10, 0);
		world.setBlock(i + 0, j + 5, k + 13, 0);
		world.setBlock(i + 0, j + 6, k + 0, 0);
		world.setBlock(i + 0, j + 6, k + 1, 0);
		world.setBlock(i + 0, j + 6, k + 2, 0);
		world.setBlock(i + 0, j + 6, k + 3, 0);
		world.setBlock(i + 0, j + 6, k + 4, 0);
		world.setBlock(i + 0, j + 6, k + 5, 0);
		world.setBlock(i + 0, j + 6, k + 6, 0);
		world.setBlock(i + 0, j + 6, k + 7, 0);
		world.setBlock(i + 0, j + 6, k + 8, 0);
		world.setBlock(i + 0, j + 6, k + 9, 0);
		world.setBlock(i + 0, j + 6, k + 10, 0);
		world.setBlock(i + 0, j + 6, k + 11, 0);
		world.setBlock(i + 0, j + 6, k + 12, 0);
		world.setBlock(i + 0, j + 6, k + 13, 0);
		world.setBlock(i + 0, j + 7, k + 0, 0);
		world.setBlock(i + 0, j + 7, k + 1, 0);
		world.setBlock(i + 0, j + 7, k + 2, 0);
		world.setBlock(i + 0, j + 7, k + 3, 0);
		world.setBlock(i + 0, j + 7, k + 4, 0);
		world.setBlock(i + 0, j + 7, k + 5, 0);
		world.setBlock(i + 0, j + 7, k + 6, 0);
		world.setBlock(i + 0, j + 7, k + 7, 0);
		world.setBlock(i + 0, j + 7, k + 8, 0);
		world.setBlock(i + 0, j + 7, k + 9, 0);
		world.setBlock(i + 0, j + 7, k + 10, 0);
		world.setBlock(i + 0, j + 7, k + 11, 0);
		world.setBlock(i + 0, j + 7, k + 12, 0);
		world.setBlock(i + 0, j + 7, k + 13, 0);
		world.setBlock(i + 0, j + 8, k + 0, 0);
		world.setBlock(i + 0, j + 8, k + 1, 0);
		world.setBlock(i + 0, j + 8, k + 2, 0);
		world.setBlock(i + 0, j + 8, k + 3, 0);
		world.setBlock(i + 0, j + 8, k + 4, 0);
		world.setBlock(i + 0, j + 8, k + 5, 0);
		world.setBlock(i + 0, j + 8, k + 6, 0);
		world.setBlock(i + 0, j + 8, k + 7, 0);
		world.setBlock(i + 0, j + 8, k + 8, 0);
		world.setBlock(i + 0, j + 8, k + 9, 0);
		world.setBlock(i + 0, j + 8, k + 10, 0);
		world.setBlock(i + 0, j + 8, k + 11, 0);
		world.setBlock(i + 0, j + 8, k + 12, 0);
		world.setBlock(i + 0, j + 8, k + 13, 0);
		world.setBlock(i + 0, j + 9, k + 0, 0);
		world.setBlock(i + 0, j + 9, k + 1, 0);
		world.setBlock(i + 0, j + 9, k + 2, 0);
		world.setBlock(i + 0, j + 9, k + 3, 0);
		world.setBlock(i + 0, j + 9, k + 4, 0);
		world.setBlock(i + 0, j + 9, k + 5, 0);
		world.setBlock(i + 0, j + 9, k + 6, 0);
		world.setBlock(i + 0, j + 9, k + 7, 0);
		world.setBlock(i + 0, j + 9, k + 8, 0);
		world.setBlock(i + 0, j + 9, k + 9, 0);
		world.setBlock(i + 0, j + 9, k + 10, 0);
		world.setBlock(i + 0, j + 9, k + 11, 0);
		world.setBlock(i + 0, j + 9, k + 12, 0);
		world.setBlock(i + 0, j + 9, k + 13, 0);
		world.setBlock(i + 1, j + 0, k + 0, Block.grass.blockID);
		world.setBlock(i + 1, j + 0, k + 1, Block.grass.blockID);
		world.setBlock(i + 1, j + 0, k + 2, Block.dirt.blockID);
		world.setBlock(i + 1, j + 0, k + 3, Block.dirt.blockID);
		world.setBlock(i + 1, j + 0, k + 4, Block.dirt.blockID);
		world.setBlock(i + 1, j + 0, k + 5, Block.dirt.blockID);
		world.setBlock(i + 1, j + 0, k + 6, Block.dirt.blockID);
		world.setBlock(i + 1, j + 0, k + 7, Block.dirt.blockID);
		world.setBlock(i + 1, j + 0, k + 8, Block.dirt.blockID);
		world.setBlock(i + 1, j + 0, k + 9, Block.dirt.blockID);
		world.setBlock(i + 1, j + 0, k + 10, Block.dirt.blockID);
		world.setBlock(i + 1, j + 0, k + 11, Block.dirt.blockID);
		world.setBlock(i + 1, j + 0, k + 12, Block.dirt.blockID);
		world.setBlock(i + 1, j + 0, k + 13, Block.grass.blockID);
		world.setBlock(i + 1, j + 1, k + 0, 0);
		world.setBlock(i + 1, j + 1, k + 2, Block.stoneBrick.blockID);
		world.setBlock(i + 1, j + 1, k + 3, Block.stoneBrick.blockID);
		world.setBlock(i + 1, j + 1, k + 4, Block.stoneBrick.blockID);
		world.setBlock(i + 1, j + 1, k + 5, Block.stoneBrick.blockID);
		world.setBlock(i + 1, j + 1, k + 6, Block.stoneBrick.blockID);
		world.setBlock(i + 1, j + 1, k + 7, Block.stoneBrick.blockID);
		world.setBlock(i + 1, j + 1, k + 8, Block.stoneBrick.blockID);
		world.setBlock(i + 1, j + 1, k + 9, Block.stoneBrick.blockID);
		world.setBlock(i + 1, j + 1, k + 10, Block.stoneBrick.blockID);
		world.setBlock(i + 1, j + 1, k + 11, Block.stoneBrick.blockID);
		world.setBlock(i + 1, j + 1, k + 12, Block.stoneBrick.blockID);
		world.setBlock(i + 1, j + 2, k + 0, 0);
		world.setBlock(i + 1, j + 2, k + 2, Block.stoneBrick.blockID);
		world.setBlock(i + 1, j + 2, k + 3, Block.stoneBrick.blockID);
		world.setBlock(i + 1, j + 2, k + 4, Block.stoneBrick.blockID);
		world.setBlock(i + 1, j + 2, k + 5, Block.stoneBrick.blockID);
		world.setBlock(i + 1, j + 2, k + 6, Block.stoneBrick.blockID);
		world.setBlock(i + 1, j + 2, k + 7, Block.stoneBrick.blockID);
		world.setBlock(i + 1, j + 2, k + 8, Block.stoneBrick.blockID);
		world.setBlock(i + 1, j + 2, k + 9, Block.stoneBrick.blockID);
		world.setBlock(i + 1, j + 2, k + 10, Block.stoneBrick.blockID);
		world.setBlock(i + 1, j + 2, k + 11, Block.stoneBrick.blockID);
		world.setBlock(i + 1, j + 2, k + 12, Block.stoneBrick.blockID);
		world.setBlock(i + 1, j + 3, k + 0, 0);
		world.setBlock(i + 1, j + 3, k + 2, Block.stoneBrick.blockID);
		world.setBlock(i + 1, j + 3, k + 3, Block.stoneBrick.blockID);
		world.setBlock(i + 1, j + 3, k + 4, Block.stoneBrick.blockID);
		world.setBlock(i + 1, j + 3, k + 5, Block.stoneBrick.blockID);
		world.setBlock(i + 1, j + 3, k + 6, Block.stoneBrick.blockID);
		world.setBlock(i + 1, j + 3, k + 7, Block.stoneBrick.blockID);
		world.setBlock(i + 1, j + 3, k + 8, Block.stoneBrick.blockID);
		world.setBlock(i + 1, j + 3, k + 9, Block.stoneBrick.blockID);
		world.setBlock(i + 1, j + 3, k + 10, Block.stoneBrick.blockID);
		world.setBlock(i + 1, j + 3, k + 11, Block.stoneBrick.blockID);
		world.setBlock(i + 1, j + 3, k + 12, Block.stoneBrick.blockID);
		world.setBlock(i + 1, j + 4, k + 0, 0);
		world.setBlock(i + 1, j + 4, k + 2, Block.stoneBrick.blockID);
		world.setBlock(i + 1, j + 4, k + 3, Block.stoneBrick.blockID);
		world.setBlock(i + 1, j + 4, k + 4, Block.stoneBrick.blockID);
		world.setBlock(i + 1, j + 4, k + 5, Block.stoneBrick.blockID);
		world.setBlock(i + 1, j + 4, k + 6, Block.stoneBrick.blockID);
		world.setBlock(i + 1, j + 4, k + 7, Block.stoneBrick.blockID);
		world.setBlock(i + 1, j + 4, k + 8, Block.stoneBrick.blockID);
		world.setBlock(i + 1, j + 4, k + 9, Block.stoneBrick.blockID);
		world.setBlock(i + 1, j + 4, k + 10, Block.stoneBrick.blockID);
		world.setBlock(i + 1, j + 4, k + 11, Block.stoneBrick.blockID);
		world.setBlock(i + 1, j + 4, k + 12, Block.stoneBrick.blockID);
		world.setBlock(i + 1, j + 5, k + 0, 0);
		world.setBlock(i + 1, j + 5, k + 1, 0);
		world.setBlock(i + 1, j + 5, k + 2, Block.stoneBrick.blockID);
		world.setBlock(i + 1, j + 5, k + 3, Block.stoneBrick.blockID, 1, 0);
		world.setBlock(i + 1, j + 5, k + 4, Block.stoneBrick.blockID);
		world.setBlock(i + 1, j + 5, k + 5, Block.stoneBrick.blockID);
		world.setBlock(i + 1, j + 5, k + 6, Block.stoneBrick.blockID);
		world.setBlock(i + 1, j + 5, k + 7, Block.stoneBrick.blockID);
		world.setBlock(i + 1, j + 5, k + 8, Block.stoneBrick.blockID, 1 ,0);
		world.setBlock(i + 1, j + 5, k + 9, Block.stoneBrick.blockID, 1, 0);
		world.setBlock(i + 1, j + 5, k + 10, Block.stoneBrick.blockID, 1, 0);
		world.setBlock(i + 1, j + 5, k + 11, Block.stoneBrick.blockID);
		world.setBlock(i + 1, j + 5, k + 12, Block.stoneBrick.blockID);
		world.setBlock(i + 1, j + 5, k + 13, 0);
		world.setBlock(i + 1, j + 6, k + 0, 0);
		world.setBlock(i + 1, j + 6, k + 1, 0);
		world.setBlock(i + 1, j + 6, k + 2, Block.stoneBrick.blockID);
		world.setBlock(i + 1, j + 6, k + 3, Block.stoneBrick.blockID, 1, 0);
		world.setBlock(i + 1, j + 6, k + 4, Block.stoneBrick.blockID, 1, 0);
		world.setBlock(i + 1, j + 6, k + 5, 0);
		world.setBlock(i + 1, j + 6, k + 6, 0);
		world.setBlock(i + 1, j + 6, k + 7, 0);
		world.setBlock(i + 1, j + 6, k + 8, 0);
		world.setBlock(i + 1, j + 6, k + 9, 0);
		world.setBlock(i + 1, j + 6, k + 10, Block.stoneBrick.blockID, 1 ,0);
		world.setBlock(i + 1, j + 6, k + 11, Block.stoneBrick.blockID);
		world.setBlock(i + 1, j + 6, k + 12, Block.stoneBrick.blockID);
		world.setBlock(i + 1, j + 6, k + 13, 0);
		world.setBlock(i + 1, j + 7, k + 0, 0);
		world.setBlock(i + 1, j + 7, k + 1, 0);
		world.setBlock(i + 1, j + 7, k + 2, 0);
		world.setBlock(i + 1, j + 7, k + 3, Block.stairsStoneBrick.blockID, 2 ,0);
		world.setBlock(i + 1, j + 7, k + 4, Block.stoneBrick.blockID, 1 ,0);
		world.setBlock(i + 1, j + 7, k + 5, 0);
		world.setBlock(i + 1, j + 7, k + 6, Block.stoneBrick.blockID);
		world.setBlock(i + 1, j + 7, k + 7, 0);
		world.setBlock(i + 1, j + 7, k + 8, Block.stoneBrick.blockID, 1 ,0);
		world.setBlock(i + 1, j + 7, k + 9, 0);
		world.setBlock(i + 1, j + 7, k + 10, Block.stoneBrick.blockID);
		world.setBlock(i + 1, j + 7, k + 11, Block.stairsStoneBrick.blockID, 3 ,0);
		world.setBlock(i + 1, j + 7, k + 12, 0);
		world.setBlock(i + 1, j + 7, k + 13, 0);
		world.setBlock(i + 1, j + 8, k + 0, 0);
		world.setBlock(i + 1, j + 8, k + 1, 0);
		world.setBlock(i + 1, j + 8, k + 2, 0);
		world.setBlock(i + 1, j + 8, k + 3, 0);
		world.setBlock(i + 1, j + 8, k + 4, Block.stairsStoneBrick.blockID, 2 ,0);
		world.setBlock(i + 1, j + 8, k + 5, Block.stoneBrick.blockID);
		world.setBlock(i + 1, j + 8, k + 6, Block.stoneBrick.blockID);
		world.setBlock(i + 1, j + 8, k + 7, 0);
		world.setBlock(i + 1, j + 8, k + 8, Block.stoneBrick.blockID, 1 ,0);
		world.setBlock(i + 1, j + 8, k + 9, Block.stoneBrick.blockID, 1 ,0);
		world.setBlock(i + 1, j + 8, k + 10, Block.stairsStoneBrick.blockID, 3 ,0);
		world.setBlock(i + 1, j + 8, k + 11, 0);
		world.setBlock(i + 1, j + 8, k + 12, 0);
		world.setBlock(i + 1, j + 8, k + 13, 0);
		world.setBlock(i + 1, j + 9, k + 0, 0);
		world.setBlock(i + 1, j + 9, k + 1, 0);
		world.setBlock(i + 1, j + 9, k + 2, 0);
		world.setBlock(i + 1, j + 9, k + 3, 0);
		world.setBlock(i + 1, j + 9, k + 4, 0);
		world.setBlock(i + 1, j + 9, k + 5, Block.stairsStoneBrick.blockID, 2 ,0);
		world.setBlock(i + 1, j + 9, k + 6, Block.stoneBrick.blockID);
		world.setBlock(i + 1, j + 9, k + 7, Block.stoneBrick.blockID);
		world.setBlock(i + 1, j + 9, k + 8, Block.stoneBrick.blockID);
		world.setBlock(i + 1, j + 9, k + 9, Block.stairsStoneBrick.blockID, 3 ,0);
		world.setBlock(i + 1, j + 9, k + 10, 0);
		world.setBlock(i + 1, j + 9, k + 11, 0);
		world.setBlock(i + 1, j + 9, k + 12, 0);
		world.setBlock(i + 1, j + 9, k + 13, 0);
		world.setBlock(i + 2, j + 0, k + 0, Block.grass.blockID);
		world.setBlock(i + 2, j + 0, k + 1, Block.grass.blockID);
		world.setBlock(i + 2, j + 0, k + 2, Block.dirt.blockID);
		world.setBlock(i + 2, j + 0, k + 3, Block.cobblestone.blockID);
		world.setBlock(i + 2, j + 0, k + 6, Block.cobblestone.blockID);
		world.setBlock(i + 2, j + 0, k + 7, Block.cobblestone.blockID);
		world.setBlock(i + 2, j + 0, k + 10, Block.cobblestone.blockID);
		world.setBlock(i + 2, j + 0, k + 12, Block.dirt.blockID);
		world.setBlock(i + 2, j + 0, k + 13, Block.grass.blockID);
		world.setBlock(i + 2, j + 1, k + 0, 0);
		world.setBlock(i + 2, j + 1, k + 2, Block.stoneBrick.blockID);
		world.setBlock(i + 2, j + 1, k + 3, 0);
		world.setBlock(i + 2, j + 1, k + 4, 0);
		world.setBlock(i + 2, j + 1, k + 5, 0);
		world.setBlock(i + 2, j + 1, k + 6, 0);
		world.setBlock(i + 2, j + 1, k + 7, 0);
		world.setBlock(i + 2, j + 1, k + 8, 0);
		world.setBlock(i + 2, j + 1, k + 9, 0);
		world.setBlock(i + 2, j + 1, k + 10, 0);
		world.setBlock(i + 2, j + 1, k + 12, Block.stoneBrick.blockID);
		world.setBlock(i + 2, j + 2, k + 0, 0);
		world.setBlock(i + 2, j + 2, k + 2, Block.stoneBrick.blockID);
		world.setBlock(i + 2, j + 2, k + 3, 0);
		world.setBlock(i + 2, j + 2, k + 4, 0);
		world.setBlock(i + 2, j + 2, k + 5, 0);
		world.setBlock(i + 2, j + 2, k + 6, 0);
		world.setBlock(i + 2, j + 2, k + 7, 0);
		world.setBlock(i + 2, j + 2, k + 8, 0);
		world.setBlock(i + 2, j + 2, k + 9, 0);
		world.setBlock(i + 2, j + 2, k + 10, 0);
		world.setBlock(i + 2, j + 2, k + 12, Block.stoneBrick.blockID);
		world.setBlock(i + 2, j + 3, k + 0, 0);
		world.setBlock(i + 2, j + 3, k + 2, Block.stoneBrick.blockID);
		world.setBlock(i + 2, j + 3, k + 3, Block.stoneSingleSlab.blockID, 5 ,0);
		world.setBlock(i + 2, j + 3, k + 4, Block.stoneSingleSlab.blockID, 5 ,0);
		world.setBlock(i + 2, j + 3, k + 5, Block.stoneBrick.blockID ,0 ,0);
		world.setBlock(i + 2, j + 3, k + 6, Block.stoneBrick.blockID, 3 ,0);
		world.setBlock(i + 2, j + 3, k + 7, Block.stoneBrick.blockID, 3 ,0);
		world.setBlock(i + 2, j + 3, k + 8, Block.stoneBrick.blockID, 3 ,0);
		world.setBlock(i + 2, j + 3, k + 9, Block.stoneBrick.blockID, 1 ,0);
		world.setBlock(i + 2, j + 3, k + 10, Block.stoneSingleSlab.blockID, 5 ,0);
		world.setBlock(i + 2, j + 3, k + 12, Block.stoneBrick.blockID ,0 ,0);
		world.setBlock(i + 2, j + 4, k + 0, 0);
		world.setBlock(i + 2, j + 4, k + 2, Block.stoneBrick.blockID, 1 ,0);
		world.setBlock(i + 2, j + 4, k + 3, 0);
		world.setBlock(i + 2, j + 4, k + 4, 0);
		world.setBlock(i + 2, j + 4, k + 5, 0);
		world.setBlock(i + 2, j + 4, k + 7, Blocks.tier1Enchanter.blockID);
		world.setBlock(i + 2, j + 4, k + 10, 0);
		world.setBlock(i + 2, j + 4, k + 12, Block.stoneBrick.blockID);
		world.setBlock(i + 2, j + 5, k + 0, 0);
		world.setBlock(i + 2, j + 5, k + 1, 0);
		world.setBlock(i + 2, j + 5, k + 2, Block.stoneBrick.blockID);
		world.setBlock(i + 2, j + 5, k + 3, 0);
		world.setBlock(i + 2, j + 5, k + 4, 0);
		world.setBlock(i + 2, j + 5, k + 5, 0);
		world.setBlock(i + 2, j + 5, k + 10, 0);
		world.setBlock(i + 2, j + 5, k + 12, Block.stoneBrick.blockID);
		world.setBlock(i + 2, j + 6, k + 0, 0);
		world.setBlock(i + 2, j + 6, k + 1, 0);
		world.setBlock(i + 2, j + 6, k + 2, Block.stoneBrick.blockID);
		world.setBlock(i + 2, j + 6, k + 3, 0);
		world.setBlock(i + 2, j + 6, k + 4, 0);
		world.setBlock(i + 2, j + 6, k + 5, 0);
		world.setBlock(i + 2, j + 6, k + 10, 0);
		world.setBlock(i + 2, j + 6, k + 12, Block.stoneBrick.blockID);
		world.setBlock(i + 2, j + 6, k + 13, 0);
		world.setBlock(i + 2, j + 7, k + 0, 0);
		world.setBlock(i + 2, j + 7, k + 1, 0);
		world.setBlock(i + 2, j + 7, k + 2, 0);
		world.setBlock(i + 2, j + 7, k + 3, 0);
		world.setBlock(i + 2, j + 7, k + 4, 0);
		world.setBlock(i + 2, j + 7, k + 5, 0);
		world.setBlock(i + 2, j + 7, k + 10, 0);
		world.setBlock(i + 2, j + 7, k + 11, 0);
		world.setBlock(i + 2, j + 7, k + 12, 0);
		world.setBlock(i + 2, j + 7, k + 13, 0);
		world.setBlock(i + 2, j + 8, k + 0, 0);
		world.setBlock(i + 2, j + 8, k + 1, 0);
		world.setBlock(i + 2, j + 8, k + 2, 0);
		world.setBlock(i + 2, j + 8, k + 3, 0);
		world.setBlock(i + 2, j + 8, k + 4, 0);
		world.setBlock(i + 2, j + 8, k + 5, 0);
		world.setBlock(i + 2, j + 8, k + 10, 0);
		world.setBlock(i + 2, j + 8, k + 11, 0);
		world.setBlock(i + 2, j + 8, k + 12, 0);
		world.setBlock(i + 2, j + 8, k + 13, 0);
		world.setBlock(i + 2, j + 9, k + 0, 0);
		world.setBlock(i + 2, j + 9, k + 1, 0);
		world.setBlock(i + 2, j + 9, k + 2, 0);
		world.setBlock(i + 2, j + 9, k + 3, 0);
		world.setBlock(i + 2, j + 9, k + 4, 0);
		world.setBlock(i + 2, j + 9, k + 5, 0);
		world.setBlock(i + 2, j + 9, k + 9, 0);
		world.setBlock(i + 2, j + 9, k + 10, 0);
		world.setBlock(i + 2, j + 9, k + 11, 0);
		world.setBlock(i + 2, j + 9, k + 12, 0);
		world.setBlock(i + 2, j + 9, k + 13, 0);
		world.setBlock(i + 3, j + 0, k + 0, Block.grass.blockID);
		world.setBlock(i + 3, j + 0, k + 1, Block.grass.blockID);
		world.setBlock(i + 3, j + 0, k + 2, Block.dirt.blockID);
		world.setBlock(i + 3, j + 0, k + 3, Block.cobblestone.blockID);
		world.setBlock(i + 3, j + 0, k + 5, Block.cobblestone.blockID);
		world.setBlock(i + 3, j + 0, k + 6, Block.cobblestone.blockID);
		world.setBlock(i + 3, j + 0, k + 9, Block.cobblestone.blockID);
		world.setBlock(i + 3, j + 0, k + 10, Block.cobblestone.blockID);
		world.setBlock(i + 3, j + 0, k + 12, Block.dirt.blockID);
		world.setBlock(i + 3, j + 0, k + 13, Block.grass.blockID);
		world.setBlock(i + 3, j + 1, k + 0, 0);
		world.setBlock(i + 3, j + 1, k + 2, Block.stoneBrick.blockID);
		world.setBlock(i + 3, j + 1, k + 4, 0);
		world.setBlock(i + 3, j + 1, k + 5, Block.stoneBrick.blockID);
		world.setBlock(i + 3, j + 1, k + 6, 0);
		world.setBlock(i + 3, j + 1, k + 7, 0);
		world.setBlock(i + 3, j + 1, k + 8, 0);
		world.setBlock(i + 3, j + 1, k + 9, Block.stoneBrick.blockID, 1 ,0);
		world.setBlock(i + 3, j + 1, k + 10, 0);
		world.setBlock(i + 3, j + 1, k + 11, 0);
		world.setBlock(i + 3, j + 1, k + 12, Block.stoneBrick.blockID);
		world.setBlock(i + 3, j + 2, k + 0, 0);
		world.setBlock(i + 3, j + 2, k + 2, Block.stoneBrick.blockID, 1 ,0);
		world.setBlock(i + 3, j + 2, k + 4, 0);
		world.setBlock(i + 3, j + 2, k + 5, Block.stoneBrick.blockID);
		world.setBlock(i + 3, j + 2, k + 6, 0);
		world.setBlock(i + 3, j + 2, k + 7, 0);
		world.setBlock(i + 3, j + 2, k + 8, 0);
		world.setBlock(i + 3, j + 2, k + 9, Block.stoneBrick.blockID, 1 ,0);
		world.setBlock(i + 3, j + 2, k + 10, 0);
		world.setBlock(i + 3, j + 2, k + 11, 0);
		world.setBlock(i + 3, j + 2, k + 12, Block.stoneBrick.blockID);
		world.setBlock(i + 3, j + 3, k + 0, 0);
		world.setBlock(i + 3, j + 3, k + 2, Block.stoneBrick.blockID, 1 ,0);
		world.setBlock(i + 3, j + 3, k + 4, Block.stoneSingleSlab.blockID, 5 ,0);
		world.setBlock(i + 3, j + 3, k + 5, Block.stoneBrick.blockID);
		world.setBlock(i + 3, j + 3, k + 6, Block.stoneBrick.blockID, 3 ,0);
		world.setBlock(i + 3, j + 3, k + 7, Block.stoneBrick.blockID, 3 ,0);
		world.setBlock(i + 3, j + 3, k + 8, Block.stoneBrick.blockID, 3, 0);
		world.setBlock(i + 3, j + 3, k + 9, Block.stoneBrick.blockID, 1 ,0);
		world.setBlock(i + 3, j + 3, k + 10, Block.stoneSingleSlab.blockID, 5, 0);
		world.setBlock(i + 3, j + 3, k + 11, Block.stoneSingleSlab.blockID, 5, 0);
		world.setBlock(i + 3, j + 3, k + 12, Block.stoneBrick.blockID);
		world.setBlock(i + 3, j + 4, k + 0, 0);
		world.setBlock(i + 3, j + 4, k + 2, Block.stoneBrick.blockID, 1, 0);
		world.setBlock(i + 3, j + 4, k + 4, 0);
		world.setBlock(i + 3, j + 4, k + 5, 0);
		world.setBlock(i + 3, j + 4, k + 6, 0);
		world.setBlock(i + 3, j + 4, k + 7, 0);
		world.setBlock(i + 3, j + 4, k + 8, 0);
		world.setBlock(i + 3, j + 4, k + 9, 0);
		world.setBlock(i + 3, j + 4, k + 10, 0);
		world.setBlock(i + 3, j + 4, k + 11, 0);
		world.setBlock(i + 3, j + 4, k + 12, Block.stoneBrick.blockID);
		world.setBlock(i + 3, j + 5, k + 0, 0);
		world.setBlock(i + 3, j + 5, k + 1, 0);
		world.setBlock(i + 3, j + 5, k + 2, Block.stoneBrick.blockID);
		world.setBlock(i + 3, j + 5, k + 4, 0);
		world.setBlock(i + 3, j + 5, k + 5, 0);
		world.setBlock(i + 3, j + 5, k + 6, 0);
		world.setBlock(i + 3, j + 5, k + 7, 0);
		world.setBlock(i + 3, j + 5, k + 8, 0);
		world.setBlock(i + 3, j + 5, k + 9, 0);
		world.setBlock(i + 3, j + 5, k + 10, 0);
		world.setBlock(i + 3, j + 5, k + 11, 0);
		world.setBlock(i + 3, j + 5, k + 12, Block.stoneBrick.blockID);
		world.setBlock(i + 3, j + 6, k + 0, 0);
		world.setBlock(i + 3, j + 6, k + 1, 0);
		world.setBlock(i + 3, j + 6, k + 2, Block.stairsStoneBrick.blockID, 1, 0);
		world.setBlock(i + 3, j + 6, k + 3, 0);
		world.setBlock(i + 3, j + 6, k + 4, 0);
		world.setBlock(i + 3, j + 6, k + 5, 0);
		world.setBlock(i + 3, j + 6, k + 6, 0);
		world.setBlock(i + 3, j + 6, k + 7, 0);
		world.setBlock(i + 3, j + 6, k + 8, 0);
		world.setBlock(i + 3, j + 6, k + 9, 0);
		world.setBlock(i + 3, j + 6, k + 10, 0);
		world.setBlock(i + 3, j + 6, k + 11, 0);
		world.setBlock(i + 3, j + 6, k + 12, Block.stairsStoneBrick.blockID, 1, 0);
		world.setBlock(i + 3, j + 6, k + 13, 0);
		world.setBlock(i + 3, j + 7, k + 0, 0);
		world.setBlock(i + 3, j + 7, k + 1, 0);
		world.setBlock(i + 3, j + 7, k + 2, 0);
		world.setBlock(i + 3, j + 7, k + 3, 0);
		world.setBlock(i + 3, j + 7, k + 4, 0);
		world.setBlock(i + 3, j + 7, k + 5, 0);
		world.setBlock(i + 3, j + 7, k + 6, 0);
		world.setBlock(i + 3, j + 7, k + 7, 0);
		world.setBlock(i + 3, j + 7, k + 8, 0);
		world.setBlock(i + 3, j + 7, k + 9, 0);
		world.setBlock(i + 3, j + 7, k + 10, 0);
		world.setBlock(i + 3, j + 7, k + 11, 0);
		world.setBlock(i + 3, j + 7, k + 12, 0);
		world.setBlock(i + 3, j + 7, k + 13, 0);
		world.setBlock(i + 3, j + 8, k + 0, 0);
		world.setBlock(i + 3, j + 8, k + 1, 0);
		world.setBlock(i + 3, j + 8, k + 2, 0);
		world.setBlock(i + 3, j + 8, k + 3, 0);
		world.setBlock(i + 3, j + 8, k + 4, 0);
		world.setBlock(i + 3, j + 8, k + 5, 0);
		world.setBlock(i + 3, j + 8, k + 6, 0);
		world.setBlock(i + 3, j + 8, k + 7, 0);
		world.setBlock(i + 3, j + 8, k + 8, 0);
		world.setBlock(i + 3, j + 8, k + 9, 0);
		world.setBlock(i + 3, j + 8, k + 10, 0);
		world.setBlock(i + 3, j + 8, k + 11, 0);
		world.setBlock(i + 3, j + 8, k + 12, 0);
		world.setBlock(i + 3, j + 8, k + 13, 0);
		world.setBlock(i + 3, j + 9, k + 0, 0);
		world.setBlock(i + 3, j + 9, k + 1, 0);
		world.setBlock(i + 3, j + 9, k + 2, 0);
		world.setBlock(i + 3, j + 9, k + 3, 0);
		world.setBlock(i + 3, j + 9, k + 4, 0);
		world.setBlock(i + 3, j + 9, k + 5, 0);
		world.setBlock(i + 3, j + 9, k + 6, 0);
		world.setBlock(i + 3, j + 9, k + 7, 0);
		world.setBlock(i + 3, j + 9, k + 8, 0);
		world.setBlock(i + 3, j + 9, k + 9, 0);
		world.setBlock(i + 3, j + 9, k + 10, 0);
		world.setBlock(i + 3, j + 9, k + 11, 0);
		world.setBlock(i + 3, j + 9, k + 12, 0);
		world.setBlock(i + 3, j + 9, k + 13, 0);
		world.setBlock(i + 4, j + 0, k + 0, Block.grass.blockID);
		world.setBlock(i + 4, j + 0, k + 1, Block.grass.blockID);
		world.setBlock(i + 4, j + 0, k + 2, Block.dirt.blockID);
		world.setBlock(i + 4, j + 0, k + 5, Block.cobblestone.blockID);
		world.setBlock(i + 4, j + 0, k + 7, Block.cobblestone.blockID);
		world.setBlock(i + 4, j + 0, k + 8, Block.cobblestone.blockID);
		world.setBlock(i + 4, j + 0, k + 12, Block.dirt.blockID);
		world.setBlock(i + 4, j + 0, k + 13, Block.grass.blockID);
		world.setBlock(i + 4, j + 1, k + 0, 0);
		world.setBlock(i + 4, j + 1, k + 1, 0);
		world.setBlock(i + 4, j + 1, k + 2, Block.stoneBrick.blockID);
		world.setBlock(i + 4, j + 1, k + 3, 0);
		world.setBlock(i + 4, j + 1, k + 4, 0);
		world.setBlock(i + 4, j + 1, k + 5, 0);
		world.setBlock(i + 4, j + 1, k + 6, 0);
		world.setBlock(i + 4, j + 1, k + 7, Block.stoneBrick.blockID, 1, 0);
		world.setBlock(i + 4, j + 1, k + 8, 0);
		world.setBlock(i + 4, j + 1, k + 9, 0);
		world.setBlock(i + 4, j + 1, k + 10, 0);
		world.setBlock(i + 4, j + 1, k + 11, 0);
		world.setBlock(i + 4, j + 1, k + 12, Block.stoneBrick.blockID, 1, 0);
		world.setBlock(i + 4, j + 2, k + 0, 0);
		world.setBlock(i + 4, j + 2, k + 1, 0);
		world.setBlock(i + 4, j + 2, k + 2, Block.stoneBrick.blockID, 1, 0);
		world.setBlock(i + 4, j + 2, k + 3, 0);
		world.setBlock(i + 4, j + 2, k + 4, 0);
		world.setBlock(i + 4, j + 2, k + 5, 0);
		world.setBlock(i + 4, j + 2, k + 6, 0);
		world.setBlock(i + 4, j + 2, k + 7, Block.stoneBrick.blockID, 1, 0);
		world.setBlock(i + 4, j + 2, k + 8, 0);
		world.setBlock(i + 4, j + 2, k + 9, 0);
		world.setBlock(i + 4, j + 2, k + 10, Block.stoneSingleSlab.blockID, 13, 0);
		world.setBlock(i + 4, j + 2, k + 11, 0);
		world.setBlock(i + 4, j + 2, k + 12, Block.stoneBrick.blockID);
		world.setBlock(i + 4, j + 3, k + 0, 0);
		world.setBlock(i + 4, j + 3, k + 1, 0);
		world.setBlock(i + 4, j + 3, k + 2, Block.stoneBrick.blockID, 1, 0);
		world.setBlock(i + 4, j + 3, k + 3, 0);
		world.setBlock(i + 4, j + 3, k + 4, 0);
		world.setBlock(i + 4, j + 3, k + 5, 0);
		world.setBlock(i + 4, j + 3, k + 6, Block.stoneBrick.blockID, 1, 0);
		world.setBlock(i + 4, j + 3, k + 7, Block.stoneBrick.blockID, 1, 0);
		world.setBlock(i + 4, j + 3, k + 8, Block.stoneBrick.blockID);
		world.setBlock(i + 4, j + 3, k + 9, 0);
		world.setBlock(i + 4, j + 3, k + 10, 0);
		world.setBlock(i + 4, j + 3, k + 11, 0);
		world.setBlock(i + 4, j + 3, k + 12, Block.stoneBrick.blockID, 1, 0);
		world.setBlock(i + 4, j + 4, k + 0, 0);
		world.setBlock(i + 4, j + 4, k + 1, 0);
		world.setBlock(i + 4, j + 4, k + 2, Block.stoneBrick.blockID, 1, 0);
		world.setBlock(i + 4, j + 4, k + 3, 0);
		world.setBlock(i + 4, j + 4, k + 4, 0);
		world.setBlock(i + 4, j + 4, k + 5, 0);
		world.setBlock(i + 4, j + 4, k + 6, 0);
		world.setBlock(i + 4, j + 4, k + 7, 0);
		world.setBlock(i + 4, j + 4, k + 8, 0);
		world.setBlock(i + 4, j + 4, k + 9, 0);
		world.setBlock(i + 4, j + 4, k + 10, 0);
		world.setBlock(i + 4, j + 4, k + 11, 0);
		world.setBlock(i + 4, j + 4, k + 12, Block.stoneBrick.blockID, 1, 0);
		world.setBlock(i + 4, j + 5, k + 0, 0);
		world.setBlock(i + 4, j + 5, k + 1, 0);
		world.setBlock(i + 4, j + 5, k + 2, Block.stairsStoneBrick.blockID, 1, 0);
		world.setBlock(i + 4, j + 5, k + 3, 0);
		world.setBlock(i + 4, j + 5, k + 4, 0);
		world.setBlock(i + 4, j + 5, k + 5, 0);
		world.setBlock(i + 4, j + 5, k + 6, 0);
		world.setBlock(i + 4, j + 5, k + 7, 0);
		world.setBlock(i + 4, j + 5, k + 8, 0);
		world.setBlock(i + 4, j + 5, k + 9, 0);
		world.setBlock(i + 4, j + 5, k + 10, 0);
		world.setBlock(i + 4, j + 5, k + 11, 0);
		world.setBlock(i + 4, j + 5, k + 12, Block.stairsStoneBrick.blockID, 1, 0);
		world.setBlock(i + 4, j + 5, k + 13, 0);
		world.setBlock(i + 4, j + 6, k + 0, 0);
		world.setBlock(i + 4, j + 6, k + 1, 0);
		world.setBlock(i + 4, j + 6, k + 2, 0);
		world.setBlock(i + 4, j + 6, k + 3, 0);
		world.setBlock(i + 4, j + 6, k + 4, 0);
		world.setBlock(i + 4, j + 6, k + 5, 0);
		world.setBlock(i + 4, j + 6, k + 6, 0);
		world.setBlock(i + 4, j + 6, k + 7, 0);
		world.setBlock(i + 4, j + 6, k + 8, 0);
		world.setBlock(i + 4, j + 6, k + 9, 0);
		world.setBlock(i + 4, j + 6, k + 10, 0);
		world.setBlock(i + 4, j + 6, k + 11, 0);
		world.setBlock(i + 4, j + 6, k + 12, 0);
		world.setBlock(i + 4, j + 6, k + 13, 0);
		world.setBlock(i + 4, j + 7, k + 0, 0);
		world.setBlock(i + 4, j + 7, k + 1, 0);
		world.setBlock(i + 4, j + 7, k + 2, 0);
		world.setBlock(i + 4, j + 7, k + 3, 0);
		world.setBlock(i + 4, j + 7, k + 4, 0);
		world.setBlock(i + 4, j + 7, k + 5, 0);
		world.setBlock(i + 4, j + 7, k + 6, 0);
		world.setBlock(i + 4, j + 7, k + 7, 0);
		world.setBlock(i + 4, j + 7, k + 8, 0);
		world.setBlock(i + 4, j + 7, k + 9, 0);
		world.setBlock(i + 4, j + 7, k + 10, 0);
		world.setBlock(i + 4, j + 7, k + 11, 0);
		world.setBlock(i + 4, j + 7, k + 12, 0);
		world.setBlock(i + 4, j + 7, k + 13, 0);
		world.setBlock(i + 4, j + 8, k + 0, 0);
		world.setBlock(i + 4, j + 8, k + 1, 0);
		world.setBlock(i + 4, j + 8, k + 2, 0);
		world.setBlock(i + 4, j + 8, k + 3, 0);
		world.setBlock(i + 4, j + 8, k + 4, 0);
		world.setBlock(i + 4, j + 8, k + 5, 0);
		world.setBlock(i + 4, j + 8, k + 6, 0);
		world.setBlock(i + 4, j + 8, k + 7, 0);
		world.setBlock(i + 4, j + 8, k + 8, 0);
		world.setBlock(i + 4, j + 8, k + 9, 0);
		world.setBlock(i + 4, j + 8, k + 10, 0);
		world.setBlock(i + 4, j + 8, k + 11, 0);
		world.setBlock(i + 4, j + 8, k + 12, 0);
		world.setBlock(i + 4, j + 8, k + 13, 0);
		world.setBlock(i + 4, j + 9, k + 0, 0);
		world.setBlock(i + 4, j + 9, k + 1, 0);
		world.setBlock(i + 4, j + 9, k + 2, 0);
		world.setBlock(i + 4, j + 9, k + 3, 0);
		world.setBlock(i + 4, j + 9, k + 4, 0);
		world.setBlock(i + 4, j + 9, k + 5, 0);
		world.setBlock(i + 4, j + 9, k + 6, 0);
		world.setBlock(i + 4, j + 9, k + 7, 0);
		world.setBlock(i + 4, j + 9, k + 8, 0);
		world.setBlock(i + 4, j + 9, k + 9, 0);
		world.setBlock(i + 4, j + 9, k + 10, 0);
		world.setBlock(i + 4, j + 9, k + 11, 0);
		world.setBlock(i + 4, j + 9, k + 12, 0);
		world.setBlock(i + 4, j + 9, k + 13, 0);
		world.setBlock(i + 5, j + 0, k + 0, Block.grass.blockID);
		world.setBlock(i + 5, j + 0, k + 1, Block.grass.blockID);
		world.setBlock(i + 5, j + 0, k + 2, Block.dirt.blockID);
		world.setBlock(i + 5, j + 0, k + 5, Block.cobblestone.blockID);
		world.setBlock(i + 5, j + 0, k + 8, Block.cobblestone.blockID);
		world.setBlock(i + 5, j + 0, k + 10, Block.cobblestone.blockID);
		world.setBlock(i + 5, j + 0, k + 12, Block.dirt.blockID);
		world.setBlock(i + 5, j + 0, k + 13, Block.grass.blockID);
		world.setBlock(i + 5, j + 1, k + 0, 0);
		world.setBlock(i + 5, j + 1, k + 2, Block.stoneBrick.blockID);
		world.setBlock(i + 5, j + 1, k + 3, 0);
		world.setBlock(i + 5, j + 1, k + 4, 0);
		world.setBlock(i + 5, j + 1, k + 5, 0);
		world.setBlock(i + 5, j + 1, k + 6, 0);
		world.setBlock(i + 5, j + 1, k + 7, 0);
		world.setBlock(i + 5, j + 1, k + 8, 0);
		world.setBlock(i + 5, j + 1, k + 9, 0);
		world.setBlock(i + 5, j + 1, k + 10, 0);
		world.setBlock(i + 5, j + 1, k + 11, 0);
		world.setBlock(i + 5, j + 1, k + 12, Block.stoneBrick.blockID, 1, 0);
		world.setBlock(i + 5, j + 1, k + 13, 0);
		world.setBlock(i + 5, j + 2, k + 0, 0);
		world.setBlock(i + 5, j + 2, k + 2, Block.stoneBrick.blockID);
		world.setBlock(i + 5, j + 2, k + 3, Block.stoneSingleSlab.blockID, 5, 0);
		world.setBlock(i + 5, j + 2, k + 4, 0);
		world.setBlock(i + 5, j + 2, k + 5, 0);
		world.setBlock(i + 5, j + 2, k + 6, 0);
		world.setBlock(i + 5, j + 2, k + 7, 0);
		world.setBlock(i + 5, j + 2, k + 8, 0);
		world.setBlock(i + 5, j + 2, k + 9, 0);
		world.setBlock(i + 5, j + 2, k + 10, 0);
		world.setBlock(i + 5, j + 2, k + 11, 0);
		world.setBlock(i + 5, j + 2, k + 12, Block.stoneBrick.blockID);
		world.setBlock(i + 5, j + 2, k + 13, 0);
		world.setBlock(i + 5, j + 3, k + 0, 0);
		world.setBlock(i + 5, j + 3, k + 2, Block.stoneBrick.blockID);
		world.setBlock(i + 5, j + 3, k + 3, 0);
		world.setBlock(i + 5, j + 3, k + 4, 0);
		world.setBlock(i + 5, j + 3, k + 5, 0);
		world.setBlock(i + 5, j + 3, k + 6, 0);
		world.setBlock(i + 5, j + 3, k + 7, 0);
		world.setBlock(i + 5, j + 3, k + 8, 0);
		world.setBlock(i + 5, j + 3, k + 9, 0);
		world.setBlock(i + 5, j + 3, k + 10, 0);
		world.setBlock(i + 5, j + 3, k + 11, 0);
		world.setBlock(i + 5, j + 3, k + 12, Block.stoneBrick.blockID, 1, 0);
		world.setBlock(i + 5, j + 3, k + 13, 0);
		world.setBlock(i + 5, j + 4, k + 0, 0);
		world.setBlock(i + 5, j + 4, k + 1, 0);
		world.setBlock(i + 5, j + 4, k + 2, Block.stairsStoneBrick.blockID, 1, 0);
		world.setBlock(i + 5, j + 4, k + 3, 0);
		world.setBlock(i + 5, j + 4, k + 4, 0);
		world.setBlock(i + 5, j + 4, k + 5, 0);
		world.setBlock(i + 5, j + 4, k + 6, 0);
		world.setBlock(i + 5, j + 4, k + 7, 0);
		world.setBlock(i + 5, j + 4, k + 8, 0);
		world.setBlock(i + 5, j + 4, k + 9, 0);
		world.setBlock(i + 5, j + 4, k + 10, 0);
		world.setBlock(i + 5, j + 4, k + 11, 0);
		world.setBlock(i + 5, j + 4, k + 12, Block.stairsStoneBrick.blockID, 1, 0);
		world.setBlock(i + 5, j + 4, k + 13, 0);
		world.setBlock(i + 5, j + 5, k + 0, 0);
		world.setBlock(i + 5, j + 5, k + 1, 0);
		world.setBlock(i + 5, j + 5, k + 2, 0);
		world.setBlock(i + 5, j + 5, k + 3, 0);
		world.setBlock(i + 5, j + 5, k + 4, 0);
		world.setBlock(i + 5, j + 5, k + 5, 0);
		world.setBlock(i + 5, j + 5, k + 6, 0);
		world.setBlock(i + 5, j + 5, k + 7, 0);
		world.setBlock(i + 5, j + 5, k + 8, 0);
		world.setBlock(i + 5, j + 5, k + 9, 0);
		world.setBlock(i + 5, j + 5, k + 10, 0);
		world.setBlock(i + 5, j + 5, k + 11, 0);
		world.setBlock(i + 5, j + 5, k + 12, 0);
		world.setBlock(i + 5, j + 5, k + 13, 0);
		world.setBlock(i + 5, j + 6, k + 0, 0);
		world.setBlock(i + 5, j + 6, k + 1, 0);
		world.setBlock(i + 5, j + 6, k + 2, 0);
		world.setBlock(i + 5, j + 6, k + 3, 0);
		world.setBlock(i + 5, j + 6, k + 4, 0);
		world.setBlock(i + 5, j + 6, k + 5, 0);
		world.setBlock(i + 5, j + 6, k + 6, 0);
		world.setBlock(i + 5, j + 6, k + 7, 0);
		world.setBlock(i + 5, j + 6, k + 8, 0);
		world.setBlock(i + 5, j + 6, k + 9, 0);
		world.setBlock(i + 5, j + 6, k + 10, 0);
		world.setBlock(i + 5, j + 6, k + 11, 0);
		world.setBlock(i + 5, j + 6, k + 12, 0);
		world.setBlock(i + 5, j + 6, k + 13, 0);
		world.setBlock(i + 5, j + 7, k + 0, 0);
		world.setBlock(i + 5, j + 7, k + 1, 0);
		world.setBlock(i + 5, j + 7, k + 2, 0);
		world.setBlock(i + 5, j + 7, k + 3, 0);
		world.setBlock(i + 5, j + 7, k + 4, 0);
		world.setBlock(i + 5, j + 7, k + 5, 0);
		world.setBlock(i + 5, j + 7, k + 6, 0);
		world.setBlock(i + 5, j + 7, k + 7, 0);
		world.setBlock(i + 5, j + 7, k + 8, 0);
		world.setBlock(i + 5, j + 7, k + 9, 0);
		world.setBlock(i + 5, j + 7, k + 10, 0);
		world.setBlock(i + 5, j + 7, k + 11, 0);
		world.setBlock(i + 5, j + 7, k + 12, 0);
		world.setBlock(i + 5, j + 7, k + 13, 0);
		world.setBlock(i + 5, j + 8, k + 0, 0);
		world.setBlock(i + 5, j + 8, k + 1, 0);
		world.setBlock(i + 5, j + 8, k + 2, 0);
		world.setBlock(i + 5, j + 8, k + 3, 0);
		world.setBlock(i + 5, j + 8, k + 4, 0);
		world.setBlock(i + 5, j + 8, k + 5, 0);
		world.setBlock(i + 5, j + 8, k + 6, 0);
		world.setBlock(i + 5, j + 8, k + 7, 0);
		world.setBlock(i + 5, j + 8, k + 8, 0);
		world.setBlock(i + 5, j + 8, k + 9, 0);
		world.setBlock(i + 5, j + 8, k + 10, 0);
		world.setBlock(i + 5, j + 8, k + 11, 0);
		world.setBlock(i + 5, j + 8, k + 12, 0);
		world.setBlock(i + 5, j + 8, k + 13, 0);
		world.setBlock(i + 5, j + 9, k + 0, 0);
		world.setBlock(i + 5, j + 9, k + 1, 0);
		world.setBlock(i + 5, j + 9, k + 2, 0);
		world.setBlock(i + 5, j + 9, k + 3, 0);
		world.setBlock(i + 5, j + 9, k + 4, 0);
		world.setBlock(i + 5, j + 9, k + 5, 0);
		world.setBlock(i + 5, j + 9, k + 6, 0);
		world.setBlock(i + 5, j + 9, k + 7, 0);
		world.setBlock(i + 5, j + 9, k + 8, 0);
		world.setBlock(i + 5, j + 9, k + 9, 0);
		world.setBlock(i + 5, j + 9, k + 10, 0);
		world.setBlock(i + 5, j + 9, k + 11, 0);
		world.setBlock(i + 5, j + 9, k + 12, 0);
		world.setBlock(i + 5, j + 9, k + 13, 0);
		world.setBlock(i + 6, j + 0, k + 0, Block.grass.blockID);
		world.setBlock(i + 6, j + 0, k + 1, Block.grass.blockID);
		world.setBlock(i + 6, j + 0, k + 2, Block.dirt.blockID);
		world.setBlock(i + 6, j + 0, k + 3, Block.cobblestone.blockID);
		world.setBlock(i + 6, j + 0, k + 7, Block.cobblestone.blockID);
		world.setBlock(i + 6, j + 0, k + 8, Block.cobblestone.blockID);
		world.setBlock(i + 6, j + 0, k + 12, Block.dirt.blockID);
		world.setBlock(i + 6, j + 0, k + 13, Block.grass.blockID);
		world.setBlock(i + 6, j + 1, k + 0, 0);
		world.setBlock(i + 6, j + 1, k + 1, 0);
		world.setBlock(i + 6, j + 1, k + 2, Block.stoneBrick.blockID);
		world.setBlock(i + 6, j + 1, k + 3, Block.stoneSingleSlab.blockID, 13, 0);
		world.setBlock(i + 6, j + 1, k + 4, 0);
		world.setBlock(i + 6, j + 1, k + 5, 0);
		world.setBlock(i + 6, j + 1, k + 6, 0);
		world.setBlock(i + 6, j + 1, k + 7, 0);
		world.setBlock(i + 6, j + 1, k + 8, 0);
		world.setBlock(i + 6, j + 1, k + 9, 0);
		world.setBlock(i + 6, j + 1, k + 10, 0);
		world.setBlock(i + 6, j + 1, k + 11, Block.stoneSingleSlab.blockID, 13, 0);
		world.setBlock(i + 6, j + 1, k + 12, Block.stoneBrick.blockID, 1, 0);
		world.setBlock(i + 6, j + 1, k + 13, 0);
		world.setBlock(i + 6, j + 2, k + 0, 0);
		world.setBlock(i + 6, j + 2, k + 1, 0);
		world.setBlock(i + 6, j + 2, k + 2, Block.stoneBrick.blockID);
		world.setBlock(i + 6, j + 2, k + 3, 0);
		world.setBlock(i + 6, j + 2, k + 4, 0);
		world.setBlock(i + 6, j + 2, k + 5, 0);
		world.setBlock(i + 6, j + 2, k + 6, 0);
		world.setBlock(i + 6, j + 2, k + 7, 0);
		world.setBlock(i + 6, j + 2, k + 8, 0);
		world.setBlock(i + 6, j + 2, k + 9, 0);
		world.setBlock(i + 6, j + 2, k + 10, 0);
		world.setBlock(i + 6, j + 2, k + 11, 0);
		world.setBlock(i + 6, j + 2, k + 12, Block.stoneBrick.blockID);
		world.setBlock(i + 6, j + 2, k + 13, 0);
		world.setBlock(i + 6, j + 3, k + 0, 0);
		world.setBlock(i + 6, j + 3, k + 1, 0);
		world.setBlock(i + 6, j + 3, k + 2, Block.stairsStoneBrick.blockID, 1, 0);
		world.setBlock(i + 6, j + 3, k + 3, 0);
		world.setBlock(i + 6, j + 3, k + 4, 0);
		world.setBlock(i + 6, j + 3, k + 5, 0);
		world.setBlock(i + 6, j + 3, k + 6, 0);
		world.setBlock(i + 6, j + 3, k + 7, 0);
		world.setBlock(i + 6, j + 3, k + 8, 0);
		world.setBlock(i + 6, j + 3, k + 9, 0);
		world.setBlock(i + 6, j + 3, k + 10, 0);
		world.setBlock(i + 6, j + 3, k + 11, 0);
		world.setBlock(i + 6, j + 3, k + 12, Block.stairsStoneBrick.blockID, 1, 0);
		world.setBlock(i + 6, j + 3, k + 13, 0);
		world.setBlock(i + 6, j + 4, k + 0, 0);
		world.setBlock(i + 6, j + 4, k + 1, 0);
		world.setBlock(i + 6, j + 4, k + 2, 0);
		world.setBlock(i + 6, j + 4, k + 3, 0);
		world.setBlock(i + 6, j + 4, k + 4, 0);
		world.setBlock(i + 6, j + 4, k + 5, 0);
		world.setBlock(i + 6, j + 4, k + 6, 0);
		world.setBlock(i + 6, j + 4, k + 7, 0);
		world.setBlock(i + 6, j + 4, k + 8, 0);
		world.setBlock(i + 6, j + 4, k + 9, 0);
		world.setBlock(i + 6, j + 4, k + 10, 0);
		world.setBlock(i + 6, j + 4, k + 11, 0);
		world.setBlock(i + 6, j + 4, k + 12, 0);
		world.setBlock(i + 6, j + 4, k + 13, 0);
		world.setBlock(i + 6, j + 5, k + 0, 0);
		world.setBlock(i + 6, j + 5, k + 1, 0);
		world.setBlock(i + 6, j + 5, k + 2, 0);
		world.setBlock(i + 6, j + 5, k + 3, 0);
		world.setBlock(i + 6, j + 5, k + 4, 0);
		world.setBlock(i + 6, j + 5, k + 5, 0);
		world.setBlock(i + 6, j + 5, k + 6, 0);
		world.setBlock(i + 6, j + 5, k + 7, 0);
		world.setBlock(i + 6, j + 5, k + 8, 0);
		world.setBlock(i + 6, j + 5, k + 9, 0);
		world.setBlock(i + 6, j + 5, k + 10, 0);
		world.setBlock(i + 6, j + 5, k + 11, 0);
		world.setBlock(i + 6, j + 5, k + 12, 0);
		world.setBlock(i + 6, j + 5, k + 13, 0);
		world.setBlock(i + 6, j + 6, k + 0, 0);
		world.setBlock(i + 6, j + 6, k + 1, 0);
		world.setBlock(i + 6, j + 6, k + 2, 0);
		world.setBlock(i + 6, j + 6, k + 3, 0);
		world.setBlock(i + 6, j + 6, k + 4, 0);
		world.setBlock(i + 6, j + 6, k + 5, 0);
		world.setBlock(i + 6, j + 6, k + 6, 0);
		world.setBlock(i + 6, j + 6, k + 7, 0);
		world.setBlock(i + 6, j + 6, k + 8, 0);
		world.setBlock(i + 6, j + 6, k + 9, 0);
		world.setBlock(i + 6, j + 6, k + 10, 0);
		world.setBlock(i + 6, j + 6, k + 11, 0);
		world.setBlock(i + 6, j + 6, k + 12, 0);
		world.setBlock(i + 6, j + 6, k + 13, 0);
		world.setBlock(i + 6, j + 7, k + 0, 0);
		world.setBlock(i + 6, j + 7, k + 1, 0);
		world.setBlock(i + 6, j + 7, k + 2, 0);
		world.setBlock(i + 6, j + 7, k + 3, 0);
		world.setBlock(i + 6, j + 7, k + 4, 0);
		world.setBlock(i + 6, j + 7, k + 5, 0);
		world.setBlock(i + 6, j + 7, k + 6, 0);
		world.setBlock(i + 6, j + 7, k + 7, 0);
		world.setBlock(i + 6, j + 7, k + 8, 0);
		world.setBlock(i + 6, j + 7, k + 9, 0);
		world.setBlock(i + 6, j + 7, k + 10, 0);
		world.setBlock(i + 6, j + 7, k + 11, 0);
		world.setBlock(i + 6, j + 7, k + 12, 0);
		world.setBlock(i + 6, j + 7, k + 13, 0);
		world.setBlock(i + 6, j + 8, k + 0, 0);
		world.setBlock(i + 6, j + 8, k + 1, 0);
		world.setBlock(i + 6, j + 8, k + 2, 0);
		world.setBlock(i + 6, j + 8, k + 3, 0);
		world.setBlock(i + 6, j + 8, k + 4, 0);
		world.setBlock(i + 6, j + 8, k + 5, 0);
		world.setBlock(i + 6, j + 8, k + 6, 0);
		world.setBlock(i + 6, j + 8, k + 7, 0);
		world.setBlock(i + 6, j + 8, k + 8, 0);
		world.setBlock(i + 6, j + 8, k + 9, 0);
		world.setBlock(i + 6, j + 8, k + 10, 0);
		world.setBlock(i + 6, j + 8, k + 11, 0);
		world.setBlock(i + 6, j + 8, k + 12, 0);
		world.setBlock(i + 6, j + 8, k + 13, 0);
		world.setBlock(i + 6, j + 9, k + 0, 0);
		world.setBlock(i + 6, j + 9, k + 1, 0);
		world.setBlock(i + 6, j + 9, k + 2, 0);
		world.setBlock(i + 6, j + 9, k + 3, 0);
		world.setBlock(i + 6, j + 9, k + 4, 0);
		world.setBlock(i + 6, j + 9, k + 5, 0);
		world.setBlock(i + 6, j + 9, k + 6, 0);
		world.setBlock(i + 6, j + 9, k + 7, 0);
		world.setBlock(i + 6, j + 9, k + 8, 0);
		world.setBlock(i + 6, j + 9, k + 9, 0);
		world.setBlock(i + 6, j + 9, k + 10, 0);
		world.setBlock(i + 6, j + 9, k + 11, 0);
		world.setBlock(i + 6, j + 9, k + 12, 0);
		world.setBlock(i + 6, j + 9, k + 13, 0);
		world.setBlock(i + 7, j + 0, k + 0, Block.grass.blockID);
		world.setBlock(i + 7, j + 0, k + 1, Block.grass.blockID);
		world.setBlock(i + 7, j + 0, k + 2, Block.dirt.blockID);
		world.setBlock(i + 7, j + 0, k + 3, Block.cobblestone.blockID);
		world.setBlock(i + 7, j + 0, k + 5, Block.cobblestone.blockID);
		world.setBlock(i + 7, j + 0, k + 9, Block.cobblestone.blockID);
		world.setBlock(i + 7, j + 0, k + 13, Block.grass.blockID);
		world.setBlock(i + 7, j + 1, k + 0, 0);
		world.setBlock(i + 7, j + 1, k + 1, 0);
		world.setBlock(i + 7, j + 1, k + 2, Block.stoneBrick.blockID, 1,0);
		world.setBlock(i + 7, j + 1, k + 3, Block.stoneSingleSlab.blockID, 5, 0);
		world.setBlock(i + 7, j + 1, k + 4, Block.stoneSingleSlab.blockID, 5,0);
		world.setBlock(i + 7, j + 1, k + 5, 0);
		world.setBlock(i + 7, j + 1, k + 6, 0);
		world.setBlock(i + 7, j + 1, k + 7, 0);
		world.setBlock(i + 7, j + 1, k + 8, 0);
		world.setBlock(i + 7, j + 1, k + 9, 0);
		world.setBlock(i + 7, j + 1, k + 10, Block.stoneSingleSlab.blockID, 5, 0);
		world.setBlock(i + 7, j + 1, k + 11, Block.stoneSingleSlab.blockID, 5, 0);
		world.setBlock(i + 7, j + 1, k + 12, Block.stoneBrick.blockID);
		world.setBlock(i + 7, j + 1, k + 13, 0);
		world.setBlock(i + 7, j + 2, k + 0, 0);
		world.setBlock(i + 7, j + 2, k + 1, 0);
		world.setBlock(i + 7, j + 2, k + 2, Block.stoneBrick.blockID, 1, 0);
		world.setBlock(i + 7, j + 2, k + 3, 0);
		world.setBlock(i + 7, j + 2, k + 4, 0);
		world.setBlock(i + 7, j + 2, k + 5, 0);
		world.setBlock(i + 7, j + 2, k + 6, 0);
		world.setBlock(i + 7, j + 2, k + 7, 0);
		world.setBlock(i + 7, j + 2, k + 8, 0);
		world.setBlock(i + 7, j + 2, k + 9, 0);
		world.setBlock(i + 7, j + 2, k + 10, 0);
		world.setBlock(i + 7, j + 2, k + 11, 0);
		world.setBlock(i + 7, j + 2, k + 12, Block.stoneBrick.blockID);
		world.setBlock(i + 7, j + 2, k + 13, 0);
		world.setBlock(i + 7, j + 3, k + 0, 0);
		world.setBlock(i + 7, j + 3, k + 1, 0);
		world.setBlock(i + 7, j + 3, k + 2, 0);
		world.setBlock(i + 7, j + 3, k + 3, 0);
		world.setBlock(i + 7, j + 3, k + 4, 0);
		world.setBlock(i + 7, j + 3, k + 5, 0);
		world.setBlock(i + 7, j + 3, k + 6, 0);
		world.setBlock(i + 7, j + 3, k + 7, 0);
		world.setBlock(i + 7, j + 3, k + 8, 0);
		world.setBlock(i + 7, j + 3, k + 9, 0);
		world.setBlock(i + 7, j + 3, k + 10, 0);
		world.setBlock(i + 7, j + 3, k + 11, 0);
		world.setBlock(i + 7, j + 3, k + 12, 0);
		world.setBlock(i + 7, j + 3, k + 13, 0);
		world.setBlock(i + 7, j + 4, k + 0, 0);
		world.setBlock(i + 7, j + 4, k + 1, 0);
		world.setBlock(i + 7, j + 4, k + 2, 0);
		world.setBlock(i + 7, j + 4, k + 3, 0);
		world.setBlock(i + 7, j + 4, k + 4, 0);
		world.setBlock(i + 7, j + 4, k + 5, 0);
		world.setBlock(i + 7, j + 4, k + 6, 0);
		world.setBlock(i + 7, j + 4, k + 7, 0);
		world.setBlock(i + 7, j + 4, k + 8, 0);
		world.setBlock(i + 7, j + 4, k + 9, 0);
		world.setBlock(i + 7, j + 4, k + 10, 0);
		world.setBlock(i + 7, j + 4, k + 11, 0);
		world.setBlock(i + 7, j + 4, k + 12, 0);
		world.setBlock(i + 7, j + 4, k + 13, 0);
		world.setBlock(i + 7, j + 5, k + 0, 0);
		world.setBlock(i + 7, j + 5, k + 1, 0);
		world.setBlock(i + 7, j + 5, k + 2, 0);
		world.setBlock(i + 7, j + 5, k + 3, 0);
		world.setBlock(i + 7, j + 5, k + 4, 0);
		world.setBlock(i + 7, j + 5, k + 5, 0);
		world.setBlock(i + 7, j + 5, k + 6, 0);
		world.setBlock(i + 7, j + 5, k + 7, 0);
		world.setBlock(i + 7, j + 5, k + 8, 0);
		world.setBlock(i + 7, j + 5, k + 9, 0);
		world.setBlock(i + 7, j + 5, k + 10, 0);
		world.setBlock(i + 7, j + 5, k + 11, 0);
		world.setBlock(i + 7, j + 5, k + 12, 0);
		world.setBlock(i + 7, j + 5, k + 13, 0);
		world.setBlock(i + 7, j + 6, k + 0, 0);
		world.setBlock(i + 7, j + 6, k + 1, 0);
		world.setBlock(i + 7, j + 6, k + 2, 0);
		world.setBlock(i + 7, j + 6, k + 3, 0);
		world.setBlock(i + 7, j + 6, k + 4, 0);
		world.setBlock(i + 7, j + 6, k + 5, 0);
		world.setBlock(i + 7, j + 6, k + 6, 0);
		world.setBlock(i + 7, j + 6, k + 7, 0);
		world.setBlock(i + 7, j + 6, k + 8, 0);
		world.setBlock(i + 7, j + 6, k + 9, 0);
		world.setBlock(i + 7, j + 6, k + 10, 0);
		world.setBlock(i + 7, j + 6, k + 11, 0);
		world.setBlock(i + 7, j + 6, k + 12, 0);
		world.setBlock(i + 7, j + 6, k + 13, 0);
		world.setBlock(i + 7, j + 7, k + 0, 0);
		world.setBlock(i + 7, j + 7, k + 1, 0);
		world.setBlock(i + 7, j + 7, k + 2, 0);
		world.setBlock(i + 7, j + 7, k + 3, 0);
		world.setBlock(i + 7, j + 7, k + 4, 0);
		world.setBlock(i + 7, j + 7, k + 5, 0);
		world.setBlock(i + 7, j + 7, k + 6, 0);
		world.setBlock(i + 7, j + 7, k + 7, 0);
		world.setBlock(i + 7, j + 7, k + 8, 0);
		world.setBlock(i + 7, j + 7, k + 9, 0);
		world.setBlock(i + 7, j + 7, k + 10, 0);
		world.setBlock(i + 7, j + 7, k + 11, 0);
		world.setBlock(i + 7, j + 7, k + 12, 0);
		world.setBlock(i + 7, j + 7, k + 13, 0);
		world.setBlock(i + 7, j + 8, k + 0, 0);
		world.setBlock(i + 7, j + 8, k + 1, 0);
		world.setBlock(i + 7, j + 8, k + 2, 0);
		world.setBlock(i + 7, j + 8, k + 3, 0);
		world.setBlock(i + 7, j + 8, k + 4, 0);
		world.setBlock(i + 7, j + 8, k + 5, 0);
		world.setBlock(i + 7, j + 8, k + 6, 0);
		world.setBlock(i + 7, j + 8, k + 7, 0);
		world.setBlock(i + 7, j + 8, k + 8, 0);
		world.setBlock(i + 7, j + 8, k + 9, 0);
		world.setBlock(i + 7, j + 8, k + 10, 0);
		world.setBlock(i + 7, j + 8, k + 11, 0);
		world.setBlock(i + 7, j + 8, k + 12, 0);
		world.setBlock(i + 7, j + 8, k + 13, 0);
		world.setBlock(i + 7, j + 9, k + 0, 0);
		world.setBlock(i + 7, j + 9, k + 1, 0);
		world.setBlock(i + 7, j + 9, k + 2, 0);
		world.setBlock(i + 7, j + 9, k + 3, 0);
		world.setBlock(i + 7, j + 9, k + 4, 0);
		world.setBlock(i + 7, j + 9, k + 5, 0);
		world.setBlock(i + 7, j + 9, k + 6, 0);
		world.setBlock(i + 7, j + 9, k + 7, 0);
		world.setBlock(i + 7, j + 9, k + 8, 0);
		world.setBlock(i + 7, j + 9, k + 9, 0);
		world.setBlock(i + 7, j + 9, k + 10, 0);
		world.setBlock(i + 7, j + 9, k + 11, 0);
		world.setBlock(i + 7, j + 9, k + 12, 0);
		world.setBlock(i + 7, j + 9, k + 13, 0);
		world.setBlock(i + 8, j + 0, k + 0, Block.grass.blockID);
		world.setBlock(i + 8, j + 0, k + 1, Block.grass.blockID);
		world.setBlock(i + 8, j + 0, k + 2, Block.grass.blockID);
		world.setBlock(i + 8, j + 0, k + 3, Block.grass.blockID);
		world.setBlock(i + 8, j + 0, k + 4, Block.grass.blockID);
		world.setBlock(i + 8, j + 0, k + 5, Block.grass.blockID);
		world.setBlock(i + 8, j + 0, k + 6, Block.grass.blockID);
		world.setBlock(i + 8, j + 0, k + 7, Block.grass.blockID);
		world.setBlock(i + 8, j + 0, k + 8, Block.grass.blockID);
		world.setBlock(i + 8, j + 0, k + 9, Block.grass.blockID);
		world.setBlock(i + 8, j + 0, k + 10, Block.grass.blockID);
		world.setBlock(i + 8, j + 0, k + 11, Block.grass.blockID);
		world.setBlock(i + 8, j + 0, k + 12, Block.grass.blockID);
		world.setBlock(i + 8, j + 0, k + 13, Block.grass.blockID);
		world.setBlock(i + 8, j + 1, k + 0, 0);
		world.setBlock(i + 8, j + 1, k + 1, 0);
		world.setBlock(i + 8, j + 1, k + 2, 0);
		world.setBlock(i + 8, j + 1, k + 3, 0);
		world.setBlock(i + 8, j + 1, k + 4, 0);
		world.setBlock(i + 8, j + 1, k + 5, 0);
		world.setBlock(i + 8, j + 1, k + 6, 0);
		world.setBlock(i + 8, j + 1, k + 7, 0);
		world.setBlock(i + 8, j + 1, k + 8, 0);
		world.setBlock(i + 8, j + 1, k + 9, 0);
		world.setBlock(i + 8, j + 1, k + 10, 0);
		world.setBlock(i + 8, j + 1, k + 11, 0);
		world.setBlock(i + 8, j + 1, k + 12, 0);
		world.setBlock(i + 8, j + 1, k + 13, 0);
		world.setBlock(i + 8, j + 2, k + 0, 0);
		world.setBlock(i + 8, j + 2, k + 1, 0);
		world.setBlock(i + 8, j + 2, k + 2, 0);
		world.setBlock(i + 8, j + 2, k + 3, 0);
		world.setBlock(i + 8, j + 2, k + 4, 0);
		world.setBlock(i + 8, j + 2, k + 5, 0);
		world.setBlock(i + 8, j + 2, k + 6, 0);
		world.setBlock(i + 8, j + 2, k + 7, 0);
		world.setBlock(i + 8, j + 2, k + 8, 0);
		world.setBlock(i + 8, j + 2, k + 9, 0);
		world.setBlock(i + 8, j + 2, k + 10, 0);
		world.setBlock(i + 8, j + 2, k + 11, 0);
		world.setBlock(i + 8, j + 2, k + 12, 0);
		world.setBlock(i + 8, j + 2, k + 13, 0);
		world.setBlock(i + 8, j + 3, k + 0, 0);
		world.setBlock(i + 8, j + 3, k + 1, 0);
		world.setBlock(i + 8, j + 3, k + 2, 0);
		world.setBlock(i + 8, j + 3, k + 3, 0);
		world.setBlock(i + 8, j + 3, k + 4, 0);
		world.setBlock(i + 8, j + 3, k + 5, 0);
		world.setBlock(i + 8, j + 3, k + 6, 0);
		world.setBlock(i + 8, j + 3, k + 7, 0);
		world.setBlock(i + 8, j + 3, k + 8, 0);
		world.setBlock(i + 8, j + 3, k + 9, 0);
		world.setBlock(i + 8, j + 3, k + 10, 0);
		world.setBlock(i + 8, j + 3, k + 11, 0);
		world.setBlock(i + 8, j + 3, k + 12, 0);
		world.setBlock(i + 8, j + 3, k + 13, 0);
		world.setBlock(i + 8, j + 4, k + 0, 0);
		world.setBlock(i + 8, j + 4, k + 1, 0);
		world.setBlock(i + 8, j + 4, k + 2, 0);
		world.setBlock(i + 8, j + 4, k + 3, 0);
		world.setBlock(i + 8, j + 4, k + 4, 0);
		world.setBlock(i + 8, j + 4, k + 5, 0);
		world.setBlock(i + 8, j + 4, k + 6, 0);
		world.setBlock(i + 8, j + 4, k + 7, 0);
		world.setBlock(i + 8, j + 4, k + 8, 0);
		world.setBlock(i + 8, j + 4, k + 9, 0);
		world.setBlock(i + 8, j + 4, k + 10, 0);
		world.setBlock(i + 8, j + 4, k + 11, 0);
		world.setBlock(i + 8, j + 4, k + 12, 0);
		world.setBlock(i + 8, j + 4, k + 13, 0);
		world.setBlock(i + 8, j + 5, k + 0, 0);
		world.setBlock(i + 8, j + 5, k + 1, 0);
		world.setBlock(i + 8, j + 5, k + 2, 0);
		world.setBlock(i + 8, j + 5, k + 3, 0);
		world.setBlock(i + 8, j + 5, k + 4, 0);
		world.setBlock(i + 8, j + 5, k + 5, 0);
		world.setBlock(i + 8, j + 5, k + 6, 0);
		world.setBlock(i + 8, j + 5, k + 7, 0);
		world.setBlock(i + 8, j + 5, k + 8, 0);
		world.setBlock(i + 8, j + 5, k + 9, 0);
		world.setBlock(i + 8, j + 5, k + 10, 0);
		world.setBlock(i + 8, j + 5, k + 11, 0);
		world.setBlock(i + 8, j + 5, k + 12, 0);
		world.setBlock(i + 8, j + 5, k + 13, 0);
		world.setBlock(i + 8, j + 6, k + 0, 0);
		world.setBlock(i + 8, j + 6, k + 1, 0);
		world.setBlock(i + 8, j + 6, k + 2, 0);
		world.setBlock(i + 8, j + 6, k + 3, 0);
		world.setBlock(i + 8, j + 6, k + 4, 0);
		world.setBlock(i + 8, j + 6, k + 5, 0);
		world.setBlock(i + 8, j + 6, k + 6, 0);
		world.setBlock(i + 8, j + 6, k + 7, 0);
		world.setBlock(i + 8, j + 6, k + 8, 0);
		world.setBlock(i + 8, j + 6, k + 9, 0);
		world.setBlock(i + 8, j + 6, k + 10, 0);
		world.setBlock(i + 8, j + 6, k + 11, 0);
		world.setBlock(i + 8, j + 6, k + 12, 0);
		world.setBlock(i + 8, j + 6, k + 13, 0);
		world.setBlock(i + 8, j + 7, k + 0, 0);
		world.setBlock(i + 8, j + 7, k + 1, 0);
		world.setBlock(i + 8, j + 7, k + 2, 0);
		world.setBlock(i + 8, j + 7, k + 3, 0);
		world.setBlock(i + 8, j + 7, k + 4, 0);
		world.setBlock(i + 8, j + 7, k + 5, 0);
		world.setBlock(i + 8, j + 7, k + 6, 0);
		world.setBlock(i + 8, j + 7, k + 7, 0);
		world.setBlock(i + 8, j + 7, k + 8, 0);
		world.setBlock(i + 8, j + 7, k + 9, 0);
		world.setBlock(i + 8, j + 7, k + 10, 0);
		world.setBlock(i + 8, j + 7, k + 11, 0);
		world.setBlock(i + 8, j + 7, k + 12, 0);
		world.setBlock(i + 8, j + 7, k + 13, 0);
		world.setBlock(i + 8, j + 8, k + 0, 0);
		world.setBlock(i + 8, j + 8, k + 1, 0);
		world.setBlock(i + 8, j + 8, k + 2, 0);
		world.setBlock(i + 8, j + 8, k + 3, 0);
		world.setBlock(i + 8, j + 8, k + 4, 0);
		world.setBlock(i + 8, j + 8, k + 5, 0);
		world.setBlock(i + 8, j + 8, k + 6, 0);
		world.setBlock(i + 8, j + 8, k + 7, 0);
		world.setBlock(i + 8, j + 8, k + 8, 0);
		world.setBlock(i + 8, j + 8, k + 9, 0);
		world.setBlock(i + 8, j + 8, k + 10, 0);
		world.setBlock(i + 8, j + 8, k + 11, 0);
		world.setBlock(i + 8, j + 8, k + 12, 0);
		world.setBlock(i + 8, j + 8, k + 13, 0);
		world.setBlock(i + 8, j + 9, k + 0, 0);
		world.setBlock(i + 8, j + 9, k + 1, 0);
		world.setBlock(i + 8, j + 9, k + 2, 0);
		world.setBlock(i + 8, j + 9, k + 3, 0);
		world.setBlock(i + 8, j + 9, k + 4, 0);
		world.setBlock(i + 8, j + 9, k + 5, 0);
		world.setBlock(i + 8, j + 9, k + 6, 0);
		world.setBlock(i + 8, j + 9, k + 7, 0);
		world.setBlock(i + 8, j + 9, k + 8, 0);
		world.setBlock(i + 8, j + 9, k + 9, 0);
		world.setBlock(i + 8, j + 9, k + 10, 0);
		world.setBlock(i + 8, j + 9, k + 11, 0);
		world.setBlock(i + 8, j + 9, k + 12, 0);
		world.setBlock(i + 8, j + 9, k + 13, 0);
		world.setBlockMetadataWithNotify(i + 0, j + 1, k + 3, Block.vine.blockID, 8);
		world.setBlockMetadataWithNotify(i + 0, j + 1, k + 4, Block.vine.blockID, 8);
		world.setBlockMetadataWithNotify(i + 0, j + 1, k + 5, Block.vine.blockID, 8);
		world.setBlockMetadataWithNotify(i + 0, j + 1, k + 6, Block.vine.blockID, 8);
		world.setBlockMetadataWithNotify(i + 0, j + 1, k + 7, Block.vine.blockID, 8);
		world.setBlockMetadataWithNotify(i + 0, j + 1, k + 9, Block.vine.blockID, 8);
		world.setBlockMetadataWithNotify(i + 0, j + 1, k + 10, Block.vine.blockID, 8);
		world.setBlockMetadataWithNotify(i + 0, j + 1, k + 11, Block.vine.blockID, 8);
		world.setBlockMetadataWithNotify(i + 0, j + 1, k + 12, Block.vine.blockID, 8);
		world.setBlockMetadataWithNotify(i + 0, j + 2, k + 3, Block.vine.blockID, 8);
		world.setBlockMetadataWithNotify(i + 0, j + 2, k + 4, Block.vine.blockID, 8);
		world.setBlockMetadataWithNotify(i + 0, j + 2, k + 5, Block.vine.blockID, 8);
		world.setBlockMetadataWithNotify(i + 0, j + 2, k + 6, Block.vine.blockID, 8);
		world.setBlockMetadataWithNotify(i + 0, j + 2, k + 7, Block.vine.blockID, 8);
		world.setBlockMetadataWithNotify(i + 0, j + 2, k + 9, Block.vine.blockID, 8);
		world.setBlockMetadataWithNotify(i + 0, j + 2, k + 10, Block.vine.blockID, 8);
		world.setBlockMetadataWithNotify(i + 0, j + 2, k + 11, Block.vine.blockID, 8);
		world.setBlockMetadataWithNotify(i + 0, j + 2, k + 12, Block.vine.blockID, 8);
		world.setBlockMetadataWithNotify(i + 0, j + 3, k + 3, Block.vine.blockID, 8);
		world.setBlockMetadataWithNotify(i + 0, j + 3, k + 4, Block.vine.blockID, 8);
		world.setBlockMetadataWithNotify(i + 0, j + 3, k + 5, Block.vine.blockID, 8);
		world.setBlockMetadataWithNotify(i + 0, j + 3, k + 6, Block.vine.blockID, 8);
		world.setBlockMetadataWithNotify(i + 0, j + 3, k + 7, Block.vine.blockID, 8);
		world.setBlockMetadataWithNotify(i + 0, j + 3, k + 9, Block.vine.blockID, 8);
		world.setBlockMetadataWithNotify(i + 0, j + 3, k + 10, Block.vine.blockID, 8);
		world.setBlockMetadataWithNotify(i + 0, j + 3, k + 11, Block.vine.blockID, 8);
		world.setBlockMetadataWithNotify(i + 0, j + 3, k + 12, Block.vine.blockID, 8);
		world.setBlockMetadataWithNotify(i + 0, j + 4, k + 3, Block.vine.blockID, 8);
		world.setBlockMetadataWithNotify(i + 0, j + 4, k + 4, Block.vine.blockID, 8);
		world.setBlockMetadataWithNotify(i + 0, j + 4, k + 5, Block.vine.blockID, 8);
		world.setBlockMetadataWithNotify(i + 0, j + 4, k + 10, Block.vine.blockID, 8);
		world.setBlockMetadataWithNotify(i + 0, j + 4, k + 11, Block.vine.blockID, 8);
		world.setBlockMetadataWithNotify(i + 0, j + 4, k + 12, Block.vine.blockID, 8);
		world.setBlockMetadataWithNotify(i + 0, j + 5, k + 3, Block.vine.blockID, 8);
		world.setBlockMetadataWithNotify(i + 0, j + 5, k + 4, Block.vine.blockID, 8);
		world.setBlockMetadataWithNotify(i + 0, j + 5, k + 11, Block.vine.blockID, 8);
		world.setBlockMetadataWithNotify(i + 0, j + 5, k + 12, Block.vine.blockID, 8);
		world.setBlockMetadataWithNotify(i + 1, j + 1, k + 1, Block.vine.blockID, 1);
		world.setBlockMetadataWithNotify(i + 1, j + 1, k + 13, Block.vine.blockID, 4);
		world.setBlockMetadataWithNotify(i + 1, j + 2, k + 1, Block.vine.blockID, 1);
		world.setBlockMetadataWithNotify(i + 1, j + 2, k + 13, Block.vine.blockID, 4);
		world.setBlockMetadataWithNotify(i + 1, j + 3, k + 1, Block.vine.blockID, 1);
		world.setBlockMetadataWithNotify(i + 1, j + 3, k + 13, Block.vine.blockID, 4);
		world.setBlockMetadataWithNotify(i + 1, j + 4, k + 1, Block.vine.blockID, 1);
		world.setBlockMetadataWithNotify(i + 1, j + 4, k + 13, Block.vine.blockID, 4);
		world.setBlock(i + 2, j + 0, k + 4, Block.gravel.blockID);
		world.setBlock(i + 2, j + 0, k + 5, Block.gravel.blockID);
		world.setBlock(i + 2, j + 0, k + 8, Block.gravel.blockID);
		world.setBlock(i + 2, j + 0, k + 9, Block.gravel.blockID);
		world.setBlock(i + 2, j + 0, k + 11, Block.gravel.blockID);
		world.setBlockMetadataWithNotify(i + 2, j + 1, k + 1, Block.vine.blockID, 1);
		world.setBlockMetadataWithNotify(i + 2, j + 1, k + 11, Block.vine.blockID, 2);
		world.setBlockMetadataWithNotify(i + 2, j + 1, k + 13, Block.vine.blockID, 4);
		world.setBlockMetadataWithNotify(i + 2, j + 2, k + 1, Block.vine.blockID, 1);
		world.setBlockMetadataWithNotify(i + 2, j + 2, k + 11, Block.vine.blockID, 2);
		world.setBlockMetadataWithNotify(i + 2, j + 2, k + 13, Block.vine.blockID, 4);
		world.setBlockMetadataWithNotify(i + 2, j + 3, k + 1, Block.vine.blockID, 1);
		world.setBlockMetadataWithNotify(i + 2, j + 3, k + 11, Block.vine.blockID, 2);
		world.setBlockMetadataWithNotify(i + 2, j + 3, k + 13, Block.vine.blockID, 4);
		world.setBlockMetadataWithNotify(i + 2, j + 4, k + 1, Block.vine.blockID, 1);
		world.setBlockMetadataWithNotify(i + 2, j + 4, k + 6, Block.vine.blockID, 2);
		world.setBlockMetadataWithNotify(i + 2, j + 4, k + 8, Block.vine.blockID, 2);
		world.setBlockMetadataWithNotify(i + 2, j + 4, k + 9, Block.vine.blockID, 2);
		world.setBlockMetadataWithNotify(i + 2, j + 4, k + 11, Block.vine.blockID, 2);
		world.setBlockMetadataWithNotify(i + 2, j + 4, k + 13, Block.vine.blockID, 4);
		world.setBlockMetadataWithNotify(i + 2, j + 5, k + 6, Block.vine.blockID, 2);
		world.setBlockMetadataWithNotify(i + 2, j + 5, k + 7, Block.vine.blockID, 2);
		world.setBlockMetadataWithNotify(i + 2, j + 5, k + 8, Block.vine.blockID, 2);
		world.setBlockMetadataWithNotify(i + 2, j + 5, k + 9, Block.vine.blockID, 2);
		world.setBlockMetadataWithNotify(i + 2, j + 5, k + 11, Block.vine.blockID, 2);
		world.setBlockMetadataWithNotify(i + 2, j + 5, k + 13, Block.vine.blockID, 4);
		world.setBlockMetadataWithNotify(i + 2, j + 6, k + 6, Block.vine.blockID, 2);
		world.setBlockMetadataWithNotify(i + 2, j + 6, k + 7, Block.vine.blockID, 2);
		world.setBlockMetadataWithNotify(i + 2, j + 6, k + 8, Block.vine.blockID, 2);
		world.setBlockMetadataWithNotify(i + 2, j + 6, k + 9, Block.vine.blockID, 2);
		world.setBlockMetadataWithNotify(i + 2, j + 6, k + 11, Block.vine.blockID, 2);
		world.setBlockMetadataWithNotify(i + 2, j + 7, k + 6, Block.vine.blockID, 2);
		world.setBlockMetadataWithNotify(i + 2, j + 7, k + 7, Block.vine.blockID, 2);
		world.setBlockMetadataWithNotify(i + 2, j + 7, k + 8, Block.vine.blockID, 2);
		world.setBlockMetadataWithNotify(i + 2, j + 7, k + 9, Block.vine.blockID, 2);
		world.setBlockMetadataWithNotify(i + 2, j + 8, k + 6, Block.vine.blockID, 2);
		world.setBlockMetadataWithNotify(i + 2, j + 8, k + 7, Block.vine.blockID, 2);
		world.setBlockMetadataWithNotify(i + 2, j + 8, k + 8, Block.vine.blockID, 2);
		world.setBlockMetadataWithNotify(i + 2, j + 8, k + 9, Block.vine.blockID, 2);
		world.setBlockMetadataWithNotify(i + 2, j + 9, k + 6, Block.vine.blockID, 2);
		world.setBlockMetadataWithNotify(i + 2, j + 9, k + 7, Block.vine.blockID, 2);
		world.setBlockMetadataWithNotify(i + 2, j + 9, k + 8, Block.vine.blockID, 2);
		world.setBlock(i + 3, j + 0, k + 4, Block.gravel.blockID);
		world.setBlock(i + 3, j + 0, k + 7, Block.gravel.blockID);
		world.setBlock(i + 3, j + 0, k + 8, Block.gravel.blockID);
		world.setBlock(i + 3, j + 0, k + 11, Block.gravel.blockID);
		world.setBlockMetadataWithNotify(i + 3, j + 1, k + 1, Block.vine.blockID, 1);
		world.setBlockMetadataWithNotify(i + 3, j + 1, k + 3, Block.vine.blockID, 4);
		world.setBlockMetadataWithNotify(i + 3, j + 1, k + 13, Block.vine.blockID, 4);
		world.setBlockMetadataWithNotify(i + 3, j + 2, k + 1, Block.vine.blockID, 1);
		world.setBlockMetadataWithNotify(i + 3, j + 2, k + 3, Block.vine.blockID, 4);
		world.setBlockMetadataWithNotify(i + 3, j + 2, k + 13, Block.vine.blockID, 4);
		world.setBlockMetadataWithNotify(i + 3, j + 3, k + 1, Block.vine.blockID, 1);
		world.setBlockMetadataWithNotify(i + 3, j + 3, k + 3, Block.vine.blockID, 4);
		world.setBlockMetadataWithNotify(i + 3, j + 3, k + 13, Block.vine.blockID, 4);
		world.setBlockMetadataWithNotify(i + 3, j + 4, k + 1, Block.vine.blockID, 1);
		world.setBlockMetadataWithNotify(i + 3, j + 4, k + 3, Block.vine.blockID, 4);
		world.setBlockMetadataWithNotify(i + 3, j + 4, k + 13, Block.vine.blockID, 4);
		world.setBlockMetadataWithNotify(i + 3, j + 5, k + 3, Block.vine.blockID, 4);
		world.setBlockMetadataWithNotify(i + 3, j + 5, k + 13, Block.vine.blockID, 4);
		world.setBlock(i + 4, j + 0, k + 3, Block.gravel.blockID);
		world.setBlock(i + 4, j + 0, k + 4, Block.gravel.blockID);
		world.setBlock(i + 4, j + 0, k + 6, Block.gravel.blockID);
		world.setBlock(i + 4, j + 0, k + 9, Block.gravel.blockID);
		world.setBlock(i + 4, j + 0, k + 10, Block.gravel.blockID);
		world.setBlock(i + 4, j + 0, k + 11, Block.gravel.blockID);
		world.setBlockMetadataWithNotify(i + 4, j + 1, k + 13, Block.vine.blockID, 4);
		world.setBlockMetadataWithNotify(i + 4, j + 2, k + 13, Block.vine.blockID, 4);
		world.setBlockMetadataWithNotify(i + 4, j + 3, k + 13, Block.vine.blockID, 4);
		world.setBlockMetadataWithNotify(i + 4, j + 4, k + 13, Block.vine.blockID, 4);
		world.setBlock(i + 5, j + 0, k + 3, Block.gravel.blockID);
		world.setBlock(i + 5, j + 0, k + 4, Block.gravel.blockID);
		world.setBlock(i + 5, j + 0, k + 6, Block.gravel.blockID);
		world.setBlock(i + 5, j + 0, k + 7, Block.gravel.blockID);
		world.setBlock(i + 5, j + 0, k + 9, Block.gravel.blockID);
		world.setBlock(i + 5, j + 0, k + 11, Block.gravel.blockID);
		world.setBlockMetadataWithNotify(i + 5, j + 1, k + 1, Block.vine.blockID, 1);
		world.setBlockMetadataWithNotify(i + 5, j + 2, k + 1, Block.vine.blockID, 1);
		world.setBlockMetadataWithNotify(i + 5, j + 3, k + 1, Block.vine.blockID, 1);
		world.setBlock(i + 6, j + 0, k + 4, Block.gravel.blockID);
		world.setBlock(i + 6, j + 0, k + 5, Block.gravel.blockID);
		world.setBlock(i + 6, j + 0, k + 6, Block.gravel.blockID);
		world.setBlock(i + 6, j + 0, k + 9, Block.gravel.blockID);
		world.setBlock(i + 6, j + 0, k + 10, Block.gravel.blockID);
		world.setBlock(i + 6, j + 0, k + 11, Block.gravel.blockID);
		world.setBlock(i + 7, j + 0, k + 4, Block.gravel.blockID);
		world.setBlock(i + 7, j + 0, k + 6, Block.gravel.blockID);
		world.setBlock(i + 7, j + 0, k + 7, Block.gravel.blockID);
		world.setBlock(i + 7, j + 0, k + 8, Block.gravel.blockID);
		world.setBlock(i + 7, j + 0, k + 10, Block.gravel.blockID);
		world.setBlock(i + 7, j + 0, k + 11, Block.gravel.blockID);
		world.setBlock(i + 7, j + 0, k + 12, Block.gravel.blockID);

		return true;
	}
}